Traceback (most recent call last):
  File "/home/izainea/miniconda3/lib/python3.9/site-packages/jupyter_cache/executors/utils.py", line 51, in single_nb_execution
    executenb(
  File "/home/izainea/miniconda3/lib/python3.9/site-packages/nbclient/client.py", line 1204, in execute
    return NotebookClient(nb=nb, resources=resources, km=km, **kwargs).execute()
  File "/home/izainea/miniconda3/lib/python3.9/site-packages/nbclient/util.py", line 84, in wrapped
    return just_run(coro(*args, **kwargs))
  File "/home/izainea/miniconda3/lib/python3.9/site-packages/nbclient/util.py", line 62, in just_run
    return loop.run_until_complete(coro)
  File "/home/izainea/miniconda3/lib/python3.9/asyncio/base_events.py", line 647, in run_until_complete
    return future.result()
  File "/home/izainea/miniconda3/lib/python3.9/site-packages/nbclient/client.py", line 663, in async_execute
    await self.async_execute_cell(
  File "/home/izainea/miniconda3/lib/python3.9/site-packages/nbclient/client.py", line 965, in async_execute_cell
    await self._check_raise_for_error(cell, cell_index, exec_reply)
  File "/home/izainea/miniconda3/lib/python3.9/site-packages/nbclient/client.py", line 862, in _check_raise_for_error
    raise CellExecutionError.from_cell_and_msg(cell, exec_reply_content)
nbclient.exceptions.CellExecutionError: An error occurred while executing the following cell:
------------------
#Note que si se introduce un argumento no num√©rico la funci√≥n generar√° un error
f1('hola')
------------------

[0;31m---------------------------------------------------------------------------[0m
[0;31mTypeError[0m                                 Traceback (most recent call last)
Input [0;32mIn [8][0m, in [0;36m<cell line: 2>[0;34m()[0m
[1;32m      1[0m [38;5;66;03m#Note que si se introduce un argumento no num√©rico la funci√≥n generar√° un error[39;00m
[0;32m----> 2[0m [43mf1[49m[43m([49m[38;5;124;43m'[39;49m[38;5;124;43mhola[39;49m[38;5;124;43m'[39;49m[43m)[49m

Input [0;32mIn [5][0m, in [0;36mf1[0;34m(*args)[0m
[1;32m      1[0m [38;5;28;01mdef[39;00m [38;5;21mf1[39m([38;5;241m*[39margs):
[0;32m----> 2[0m     [38;5;28;01mreturn[39;00m [38;5;28;43msum[39;49m[43m([49m[43margs[49m[43m)[49m

[0;31mTypeError[0m: unsupported operand type(s) for +: 'int' and 'str'
TypeError: unsupported operand type(s) for +: 'int' and 'str'

