Traceback (most recent call last):
  File "/home/izainea/miniconda3/lib/python3.9/site-packages/jupyter_cache/executors/utils.py", line 51, in single_nb_execution
    executenb(
  File "/home/izainea/miniconda3/lib/python3.9/site-packages/nbclient/client.py", line 1204, in execute
    return NotebookClient(nb=nb, resources=resources, km=km, **kwargs).execute()
  File "/home/izainea/miniconda3/lib/python3.9/site-packages/nbclient/util.py", line 84, in wrapped
    return just_run(coro(*args, **kwargs))
  File "/home/izainea/miniconda3/lib/python3.9/site-packages/nbclient/util.py", line 62, in just_run
    return loop.run_until_complete(coro)
  File "/home/izainea/miniconda3/lib/python3.9/asyncio/base_events.py", line 647, in run_until_complete
    return future.result()
  File "/home/izainea/miniconda3/lib/python3.9/site-packages/nbclient/client.py", line 663, in async_execute
    await self.async_execute_cell(
  File "/home/izainea/miniconda3/lib/python3.9/site-packages/nbclient/client.py", line 965, in async_execute_cell
    await self._check_raise_for_error(cell, cell_index, exec_reply)
  File "/home/izainea/miniconda3/lib/python3.9/site-packages/nbclient/client.py", line 862, in _check_raise_for_error
    raise CellExecutionError.from_cell_and_msg(cell, exec_reply_content)
nbclient.exceptions.CellExecutionError: An error occurred while executing the following cell:
------------------
if True:
print('El valor de verdad de la condici√≥n es verdadero')
------------------

[0;36m  Input [0;32mIn [3][0;36m[0m
[0;31m    print('El valor de verdad de la condici√≥n es verdadero')[0m
[0m    ^[0m
[0;31mIndentationError[0m[0;31m:[0m expected an indented block

IndentationError: expected an indented block (2548589037.py, line 2)

